Workbook

Sheet Planilha1
A1: Nome | B1: Cim
A2: Renato Garcia | B2: 204030 | C2: =VLOOKUP(B2,Planilha3!A:D,4,FALSE) -> renatojga@gmail.com
A3: Bento Oliviera | B3: 152408 | C3: =VLOOKUP(B3,Planilha3!A:D,4,FALSE) -> bento@bento.adv.br
A4: Valentin Oprea | C4: =VLOOKUP(B4,Planilha3!A:D,4,FALSE) -> #N/A
A5: Savino Sashov Batanov | C5: =VLOOKUP(B5,Planilha3!A:D,4,FALSE) -> #N/A
A6: Carl Ek | C6: =VLOOKUP(B6,Planilha3!A:D,4,FALSE) -> #N/A
A7: Bonislav Dishkov | C7: =VLOOKUP(B7,Planilha3!A:D,4,FALSE) -> #N/A
A8: Pedro Villanueva | C8: =VLOOKUP(B8,Planilha3!A:D,4,FALSE) -> #N/A
A9: Peter Larsen | C9: =VLOOKUP(B9,Planilha3!A:D,4,FALSE) -> #N/A
A10: Claude Nzeza Zi Ngeti | C10: =VLOOKUP(B10,Planilha3!A:D,4,FALSE) -> #N/A
A11: Raul Lopes | C11: =VLOOKUP(B11,Planilha3!A:D,4,FALSE) -> #N/A
A12: François Benhamou | C12: =VLOOKUP(B12,Planilha3!A:D,4,FALSE) -> #N/A
A13: Patrick Avram | C13: =VLOOKUP(B13,Planilha3!A:D,4,FALSE) -> #N/A
A14: Rui Stragliotto | C14: =VLOOKUP(B14,Planilha3!A:D,4,FALSE) -> #N/A
A15: Assis Mentor de Mello Filho | B15: 167673 | C15: =VLOOKUP(B15,Planilha3!A:D,4,FALSE) -> assis.mentor@gmail.com
A16: Everson Craveiro | B16: 227314 | C16: =VLOOKUP(B16,Planilha3!A:D,4,FALSE) -> craveiro32@gmail.com
A17: Luiz Fernando Mokwa | B17: 192068 | C17: =VLOOKUP(B17,Planilha3!A:D,4,FALSE) -> lfmokwa@gmail.com
A18: Wagner Rodrigues | B18: 213411 | C18: =VLOOKUP(B18,Planilha3!A:D,4,FALSE) -> wmradvoc@uol.com.br
A19: Pedro Brito | C19: =VLOOKUP(B19,Planilha3!A:D,4,FALSE) -> #N/A
A20: Nelson Luiz Frare | B20: 172785 | C20: =VLOOKUP(B20,Planilha3!A:D,4,FALSE) -> n.frare@uol.com.br
A21: José Vinholi Júnior | B21: 198895 | C21: =VLOOKUP(B21,Planilha3!A:D,4,FALSE) -> vin.junior@terra.com.br
A22: Ângelo Berto | B22: 209075 | C22: =VLOOKUP(B22,Planilha3!A:D,4,FALSE) -> gilimberto@yahoo.com.br
A23: Eduardo Tomanik | B23: 246820 | C23: =VLOOKUP(B23,Planilha3!A:D,4,FALSE) -> eduardo@ejtl.com.br
A24: Benedito Marques Ballouk Filho | B24: 134406 | C24: =VLOOKUP(B24,Planilha3!A:D,4,FALSE) -> benedito.ballouk@hotmail.com
A25: Raimundo Hermes Barbosa | B25: 128589 | C25: =VLOOKUP(B25,Planilha3!A:D,4,FALSE) -> hermes.barbosa@barbosaadv.com.br
A26: Alfredo Henrique Pugliese | B26: 172763 | C26: =VLOOKUP(B26,Planilha3!A:D,4,FALSE) -> pugliesepericias@uol.com.br
A27: Aureo Bernardo Junior | B27: 249831 | C27: =VLOOKUP(B27,Planilha3!A:D,4,FALSE) -> aureo.bernardo@bernardoadvocacia.com.br
A28: Mauro Tippi | B28: 158570 | C28: =VLOOKUP(B28,Planilha3!A:D,4,FALSE) -> mauro.tippi@gmail.com
C29: =VLOOKUP(B29,Planilha3!A:D,4,FALSE) -> #N/A
C30: =VLOOKUP(B30,Planilha3!A:D,4,FALSE) -> #N/A
A31: Lista de Staff | C31: =VLOOKUP(B31,Planilha3!A:D,4,FALSE) -> #N/A
A32: Antonio Carlos Pereira Gomes | B32: 183958 | C32: =VLOOKUP(B32,Planilha3!A:D,4,FALSE) -> secr.universitaria@gmail.com
A33: Paulo Limiro | B33: 226212 | C33: =VLOOKUP(B33,Planilha3!A:D,4,FALSE) -> plimiro@hotmail.com
A34: Francis Bassi | B34: 233406 | C34: =VLOOKUP(B34,Planilha3!A:D,4,FALSE) -> francis@acovisa.com.br
A35: Alfeu Doria | B35: 263830 | C35: =VLOOKUP(B35,Planilha3!A:D,4,FALSE) -> #N/A
A36: Omar Zacharias | B36: 188483 | C36: =VLOOKUP(B36,Planilha3!A:D,4,FALSE) -> omar.zacharias@gosp.org.br
A37: Helio Alvarez | B37: 233926 | C37: =VLOOKUP(B37,Planilha3!A:D,4,FALSE) -> helioamandara@gmail.com
A38: Everth Bonavolonta | B38: 306378 | C38: =VLOOKUP(B38,Planilha3!A:D,4,FALSE) -> #N/A
A39: Sergio Vieira | B39: 291266 | C39: =VLOOKUP(B39,Planilha3!A:D,4,FALSE) -> sernan.lima@gmail.com
A40: Raphael Lima | B40: 500530 | C40: =VLOOKUP(B40,Planilha3!A:D,4,FALSE) -> #N/A
...

Sheet Planilha2
A1: CIM | B1: ID | C1: CodigoEmail | D1: Contato | E1: DataCadastro | F1: HoraCadastro | G1: MEMBRO | H1: PermissaoAPP | I1: Status | J1: Tipo
A2: 233406 | B2: 41 | C2: E73313 | D2: francis@acovisa.com.br | G2: 3 | I2: Confirmado | J2: Email
A3: 158570 | B3: 63 | C3: E53058 | D3: mauro.tippi@gmail.com | G3: 50 | I3: Confirmado | J3: Email
A4: 158570 | B4: 66 | C4: E16096 | D4: gosp@com.br | G4: 50 | I4: Pendente | J4: Email
A5: 172785 | B5: 169 | C5: E82536 | D5: n.frare@uol.com.br | E5: 42231 | F5: 0.67592593 | G5: 122 | I5: Confirmado | J5: Email
A6: 188483 | B6: 252 | C6: E71860 | D6: omar.zacharias@gosp.org.br | E6: 42234 | F6: 0.49142361 | G6: 18 | I6: Confirmado | J6: Email
A7: 198895 | B7: 541 | C7: E28324 | D7: vin.junior@terra.com.br | E7: 42238 | F7: 0.77318287 | G7: 46715 | I7: Confirmado | J7: Email
A8: 291266 | B8: 671 | C8: E40148 | D8: sernan.lima@gmail.com | E8: 42239 | F8: 0.58758102 | G8: 12214 | I8: Confirmado | J8: Email
A9: 246820 | B9: 781 | C9: E43000 | D9: eduardo@ejtl.com.br | E9: 42240 | F9: 0.3972338 | G9: 8677 | I9: Confirmado | J9: Email
A10: 183315 | B10: 1081 | C10: E39234 | D10: sergio@qualyfiltros.com.br | E10: 42243 | F10: 0.87180556 | G10: 90 | I10: Confirmado | J10: Email
A11: 183315 | B11: 1082 | D11: Whats App | E11: 42243 | F11: 0.87508102 | G11: 90 | I11: Pendente | J11: Outro
A12: 187071 | B12: 1292 | C12: E34608 | D12: m_ludovico@hotmail.com | E12: 42246 | F12: 0.5924537 | G12: 43 | I12: Confirmado | J12: Email
A13: 216618 | B13: 1374 | C13: E97224 | D13: dayvi@mizrahi.eu | E13: 42247 | F13: 0.50177083 | G13: 23930 | I13: Confirmado | J13: Email
A14: 226212 | B14: 2498 | C14: E40476 | D14: plimiro@hotmail.com | E14: 42251 | F14: 0.64543981 | G14: 22878 | I14: Confirmado | J14: Email
A15: 263976 | B15: 2586 | C15: E66488 | D15: sd-silva2010@uol.com.br | E15: 42251 | F15: 0.90809028 | G15: 18127 | I15: Confirmado | J15: Email
A16: 134406 | B16: 3130 | C16: E86116 | D16: benedito.ballouk@hotmail.com | E16: 42255 | F16: 0.48576389 | G16: 2 | I16: Pendente | J16: Email
A17: 134406 | B17: 3357 | C17: E54298 | D17: mballouk@uol.com.br | E17: 42256 | F17: 0.041365741 | G17: 2 | I17: Confirmado | J17: Email
A18: 277934 | B18: 3957 | C18: E82350 | D18: claudiomega11@gmail.com | E18: 42257 | F18: 0.77364583 | G18: 45 | I18: Confirmado | J18: Email
A19: 277934 | B19: 4142 | C19: E4374 | D19: claudiomega11@hotmail.com | E19: 42258 | F19: 0.51185185 | G19: 45 | I19: Confirmado | J19: Email
A20: 220316 | B20: 5335 | C20: E72739 | D20: luisfelipe@geotechconsultoria.com.br | E20: 42263 | F20: 0.47850694 | G20: 23555 | I20: Confirmado | J20: Email
A21: 277632 | B21: 6146 | C21: E52000 | D21: marcio@steinbruch.com.br | E21: 42264 | F21: 0.77767361 | G21: 17562 | I21: Confirmado | J21: Email
A22: 277632 | B22: 6158 | C22: E29044 | D22: clinica@steinbruch.com.br | E22: 42264 | F22: 0.78829861 | G22: 17562 | I22: Confirmado | J22: Email
A23: 209075 | B23: 6308 | C23: E42885 | D23: gilimberto@yahoo.com.br | E23: 42265 | F23: 0.061863426 | G23: 17425 | I23: Pendente | J23: Email
... A37: 213411 | B37: 32533 | C37: E48335 | D37: wmradvoc@uol.com.br | E37: 42313 | F37: 0.5527662 | G37: 10142 | I37: Confirmado | J37: Email
A38: 213411 | B38: 32542 | D38: WAGNER RODRIGUES | E38: 42313 | F38: 0.5671875 | G38: 10142 | I38: Pendente | J38: Facebook
A39: 227314 | B39: 36265 | C39: E52571 | D39: eversonpsc@sinferp.org.br | E39: 42407 | F39: 0.62681713 | G39: 27154 | I39: Pendente | J39: Email
A40: 167673 | B40: 37891 | C40: E42683 | D40: assis.mentor@gmail.com | E40: 42460 | F40: 0.52707176 | G40: 9223 | I40: Confirmado | J40: Email
A41: 183958 | B41: 38922 | C41: E28502 | D41: antoniocarlos@culturaemcenatv.com | E41: 42479 | F41: 0.41642361 | G41: 17451 | I41: Pendente | J41: Email
A42: 216618 | B42: 39204 | C42: E55388 | D42: dayvimizrahi@gmail.com | E42: 42487 | F42: 0.47363426 | G42: 23930 | I42: Confirmado | J42: Email
A43: 134406 | B43: 41185 | C43: E81359 | D43: ballouk@ballouk.com.br | E43: 42568 | F43: 0.50002315 | G43: 2 | I43: Pendente | J43: Email
A44: 233406 | B44: 44053 | C44: E292 | D44: francis.bassi@gosp.org.br | E44: 42873 | F44: 0.6505787 | G44: 3 | I44: Confirmado | J44: Email
A45: 233926 | B45: 45317 | C45: E60307 | D45: helioamandara@gmail.com | E45: 42947 | F45: 0.66365741 | G45: 33938 | I45: Pendente | J45: Email
A46: 128589 | B46: 48935 | C46: E8357 | D46: hermes.barbosa@barbosaadv.com.br | E46: 43343 | F46: 0.48490741 | G46: 6350 | H46: 0 | I46: Confirmado | J46: Email

Sheet Planilha3
A1: CIM | B1: ID | C1: CodigoEmail | D1: Contato | E1: DataCadastro | F1: HoraCadastro | G1: MEMBRO | H1: PermissaoAPP | I1: Status | J1: Tipo
A2: 233406 | B2: 41 | C2: E73313 | D2: francis@acovisa.com.br | G2: 3 | I2: Confirmado | J2: Email
A3: 158570 | B3: 63 | C3: E53058 | D3: mauro.tippi@gmail.com | G3: 50 | I3: Confirmado | J3: Email
A4: 158570 | B4: 66 | C4: E16096 | D4: gosp@com.br | G4: 50 | I4: Pendente | J4: Email
A5: 172785 | B5: 169 | C5: E82536 | D5: n.frare@uol.com.br | E5: 42231 | F5: 0.67592593 | G5: 122 | I5: Confirmado | J5: Email
A6: 188483 | B6: 252 | C6: E71860 | D6: omar.zacharias@gosp.org.br | E6: 42234 | F6: 0.49142361 | G6: 18 | I6: Confirmado | J6: Email
A7: 198895 | B7: 541 | C7: E28324 | D7: vin.junior@terra.com.br | E7: 42238 | F7: 0.77318287 | G7: 46715 | I7: Confirmado | J7: Email
A8: 291266 | B8: 671 | C8: E40148 | D8: sernan.lima@gmail.com | E8: 42239 | F8: 0.58758102 | G8: 12214 | I8: Confirmado | J8: Email
A9: 246820 | B9: 781 | C9: E43000 | D9: eduardo@ejtl.com.br | E9: 42240 | F9: 0.3972338 | G9: 8677 | I9: Confirmado | J9: Email
A10: 183315 | B10: 1081 | C10: E39234 | D10: sergio@qualyfiltros.com.br | E10: 42243 | F10: 0.87180556 | G10: 90 | I10: Confirmado | J10: Email
A11: 183315 | B11: 1082 | D11: Whats App | E11: 42243 | F11: 0.87508102 | G11: 90 | I11: Pendente | J11: Outro
A12: 187071 | B12: 1292 | C12: E34608 | D12: m_ludovico@hotmail.com | E12: 42246 | F12: 0.5924537 | G12: 43 | I12: Confirmado | J12: Email
A13: 216618 | B13: 1374 | C13: E97224 | D13: dayvi@mizrahi.eu | E13: 42247 | F13: 0.50177083 | G13: 23930 | I13: Confirmado | J13: Email
A14: 226212 | B14: 2498 | C14: E40476 | D14: plimiro@hotmail.com | E14: 42251 | F14: 0.64543981 | G14: 22878 | I14: Confirmado | J14: Email
A15: 263976 | B15: 2586 | C15: E66488 | D15: sd-silva2010@uol.com.br | E15: 42251 | F15: 0.90809028 | G15: 18127 | I15: Confirmado | J15: Email
A16: 134406 | B16: 3130 | C16: E86116 | D16: benedito.ballouk@hotmail.com | E16: 42255 | F16: 0.48576389 | G16: 2 | I16: Pendente | J16: Email
A17: 134406 | B17: 3357 | C17: E54298 | D17: mballouk@uol.com.br | E17: 42256 | F17: 0.041365741 | G17: 2 | I17: Confirmado | J17: Email
A18: 277934 | B18: 3957 | C18: E82350 | D18: claudiomega11@gmail.com | E18: 42257 | F18: 0.77364583 | G18: 45 | I18: Confirmado | J18: Email
A19: 277934 | B19: 4142 | C19: E4374 | D19: claudiomega11@hotmail.com | E19: 42258 | F19: 0.51185185 | G19: 45 | I19: Confirmado | J19: Email
A20: 220316 | B20: 5335 | C20: E72739 | D20: luisfelipe@geotechconsultoria.com.br | E20: 42263 | F20: 0.47850694 | G20: 23555 | I20: Confirmado | J20: Email
A21: 277632 | B21: 6146 | C21: E52000 | D21: marcio@steinbruch.com.br | E21: 42264 | F21: 0.77767361 | G21: 17562 | I21: Confirmado | J21: Email
A22: 277632 | B22: 6158 | C22: E29044 | D22: clinica@steinbruch.com.br | E22: 42264 | F22: 0.78829861 | G22: 17562 | I22: Confirmado | J22: Email
A23: 209075 | B23: 6308 | C23: E42885 | D23: gilimberto@yahoo.com.br | E23: 42265 | F23: 0.061863426 | G23: 17425 | I23: Pendente | J23: Email
... A37: 213411 | B37: 32533 | C37: E48335 | D37: wmradvoc@uol.com.br | E37: 42313 | F37: 0.5527662 | G37: 10142 | I37: Confirmado | J37: Email
A38: 213411 | B38: 32542 | D38: WAGNER RODRIGUES | E38: 42313 | F38: 0.5671875 | G38: 10142 | I38: Pendente | J38: Facebook
A39: 227314 | B39: 36265 | C39: E52571 | D39: eversonpsc@sinferp.org.br | E39: 42407 | F39: 0.62681713 | G39: 27154 | I39: Pendente | J39: Email
A40: 167673 | B40: 37891 | C40: E42683 | D40: assis.mentor@gmail.com | E40: 42460 | F40: 0.52707176 | G40: 9223 | I40: Confirmado | J40: Email
A41: 183958 | B41: 38922 | C41: E28502 | D41: antoniocarlos@culturaemcenatv.com | E41: 42479 | F41: 0.41642361 | G41: 17451 | I41: Pendente | J41: Email
A42: 216618 | B42: 39204 | C42: E55388 | D42: dayvimizrahi@gmail.com | E42: 42487 | F42: 0.47363426 | G42: 23930 | I42: Confirmado | J42: Email
A43: 134406 | B43: 41185 | C43: E81359 | D43: ballouk@ballouk.com.br | E43: 42568 | F43: 0.50002315 | G43: 2 | I43: Pendente | J43: Email
A44: 233406 | B44: 44053 | C44: E292 | D44: francis.bassi@gosp.org.br | E44: 42873 | F44: 0.6505787 | G44: 3 | I44: Confirmado | J44: Email
A45: 233926 | B45: 45317 | C45: E60307 | D45: helioamandara@gmail.com | E45: 42947 | F45: 0.66365741 | G45: 33938 | I45: Pendente | J45: Email
A46: 128589 | B46: 48935 | C46: E8357 | D46: hermes.barbosa@barbosaadv.com.br | E46: 43343 | F46: 0.48490741 | G46: 6350 | H46: 0 | I46: Confirmado | J46: Email
